# 异常处理

在编程过程中，**异常**指的是程序运行中发生的**不正常事件**，这些事件会**中断程序的正常执行**。当异常发生时，我们应当预先设定处理方式，确保程序在异常出现后仍能继续运行。

## `try-catch-finally`

Java 提供 5 个关键字来处理异常：`try`、`catch`、`finally`、`throw`、`throws`。

- `try`：用于包裹可能引发异常的代码块
- `catch`：用于捕获并处理异常
- `finally`：无论是否发生异常，总是执行的代码块（常用于资源释放）
- `throw`：手动抛出异常
- `throws`：声明方法可能抛出的异常类型

基本结构如下：

```java
try {
    // 可能发生异常的代码
} catch (异常类型 ex) {
    // 处理异常的代码
} finally {
    // 总是执行的代码
}
```

1. 如果 `try` 块中没有异常，则跳过 `catch` 块，直接执行 `finally`
2. 如果 `try` 块中发生异常，执行 `catch`，然后执行 `finally`
3. `finally` 块常用于资源释放操作，无论是否有异常都会执行

### 示例：除 0 异常

我们不能将数字除以 0，以下示例展示了如何处理此类异常。

```java
package scu.test_2024_10_2.package_23_53;

import java.util.Scanner;

public class Main {
    public static void main(String[] args) {
        Scanner input = new Scanner(System.in);
        System.out.println("Enter n1: ");
        int n1 = input.nextInt();
        System.out.println("Enter n2: ");
        int n2 = input.nextInt();
        try {
            int res = n1 / n2;
            System.out.println(res);
        } catch (ArithmeticException ex) {
            System.err.println("除数不能为 0");
        } finally {
            System.out.println("程序结束");
        }
    }
}
```

## 异常对象的常用方法

- `printStackTrace()`：输出异常的堆栈信息，显示异常类型、引发异常的代码位置等
- `getMessage()`：返回异常的简短描述信息

### 示例：使用 `printStackTrace()`

```java
package scu.test_2024_10_2.package_23_53;

import java.util.Scanner;

public class Main {
    public static void main(String[] args) {
        Scanner input = new Scanner(System.in);
        System.out.println("Enter n1: ");
        int n1 = input.nextInt();
        System.out.println("Enter n2: ");
        int n2 = input.nextInt();
        try {
            int res = n1 / n2;
            System.out.println(res);
        } catch (ArithmeticException ex) {
            System.err.println("除数不能为 0");
            ex.printStackTrace();
            System.out.println(ex.getMessage());
        } finally {
            System.out.println("程序结束");
        }
    }
}
```

## `finally` 与 `return`

即使在 `catch` 中有 `return`，`finally` 块中的代码依然会被执行。

```java
try {
    return;
} catch (Exception ex) {
    return;
} finally {
    System.out.println("finally 代码块");
}
```

## 多路异常捕获

一个 `try-catch` 块可以捕获多个异常，捕获顺序应从子类异常到父类异常。

### 多路异常捕获示例

```java
package scu.test_2024_10_3.package_12_34;

import java.util.InputMismatchException;
import java.util.Scanner;

public class Main {
    public static void main(String[] args) {
        Scanner input = new Scanner(System.in);
        try {
            System.out.println("Enter n1: ");
            int n1 = input.nextInt();
            System.out.println("Enter n2: ");
            int n2 = input.nextInt();
            int res = n1 / n2;
            System.out.println(res);
        } catch (InputMismatchException ex) {
            System.out.println("输入必须是整数");
        } catch (ArithmeticException ex) {
            System.out.println("除数不能为 0");
        } catch (Exception ex) {
            System.out.println("未知异常");
        } finally {
            System.out.println("程序结束");
        }
    }
}
```

> **注意**：
>
> 1. 异常捕获顺序应从子类到父类
> 2. 若发生异常，只会执行第一个匹配的 `catch` 块

## `throws` 声明异常

如果一个方法内部抛出了异常，可以通过 `throws` 将异常抛给调用方处理。

```java
package scu.test_2024_10_3.package_13_09;

public class Main {
    public static void test() throws ArithmeticException {
        System.out.println(5 / 0);
    }

    public static void main(String[] args) {
        try {
            test();
        } catch (ArithmeticException e) {
            System.out.println("除数不能为 0");
        }
    }
}
```

## `throw` 抛出异常

`throw` 用于手动抛出异常，适合自定义异常情况。

```java
package scu.test_2024_10_3.package_13_35;

public class Main {
    public static void divide(int a, int b) {
        if (b == 0) {
            throw new ArithmeticException("除数不能为 0");
        }
        System.out.println("结果为：" + a / b);
    }

    public static void main(String[] args) {
        divide(4, 0);
    }
}
```

## 异常分类

<img src="../images/image-202410031419.webp" style="zoom: 60%;" />

- **运行时异常（RuntimeException）**：运行时可能发生，但不强制要求处理
- **检查时异常**：编译时必须处理的异常，需使用 `try-catch` 或 `throws`

---

## 自定义异常

Java 允许我们定义自己的异常类来处理特定异常情况。

- 自定义异常类应继承 `Exception` 或 `RuntimeException`
- 在需要抛出自定义异常时，使用 `throw`

### 自定义异常示例

```java
package scu.test_2024_10_3.package_14_50;

class AgeException extends Exception {
    public AgeException(String msg) {
        super(msg);
    }
}

public class Main {
    public static void main(String[] args) {
        Scanner input = new Scanner(System.in);
        System.out.println("请输入姓名：");
        String name = input.next();
        System.out.println("请输入年龄：");
        try {
            int age = input.nextInt();
            if (age < 0) {
                throw new AgeException("年龄不能为负数");
            }
            System.out.println("姓名：" + name);
            System.out.println("年龄：" + age);
        } catch (AgeException e) {
            System.out.println(e.getMessage());
        }
    }
}
```

## `log4j` 日志记录

`log4j` 是一个用于记录日志的开源工具，用于输出程序中的运行信息，可以控制日志的格式和级别。

**日志级别：**

`OFF`、`FATAL`、`ERROR`、`WARN`、`INFO`、`DEBUG`、`TRACE`、`ALL`。

## 练习：方法异常处理

情境：方法 A 调用方法 B，而方法 B 中出现了异常。

### 方式一：声明异常

```java
public void methodA() throws Exception {
    methodB();
}

public void methodB() throws Exception {
    throw new Exception("异常");
}
```

### 方式二：捕获异常

```java
public void methodA() {
    try {
        methodB();
    } catch (Exception e) {
        System.out.println(e.getMessage());
    }
}

public void methodB() throws Exception {
    throw new Exception("异常");
}
```
